<?xml version="1.0" ?>
<!-- =================================================================================== -->
<!-- |    This document was autogenerated by xacro from allegro_hand_on_kuka_stl_mesh_hand.urdf.xacro | -->
<!-- |    EDITING THIS FILE BY HAND IS NOT RECOMMENDED                                 | -->
<!-- =================================================================================== -->
<robot name="LWR" xmlns:controller="http://playerstage.sourceforge.net/gazebo/xmlschema/#controller" xmlns:interface="http://playerstage.sourceforge.net/gazebo/xmlschema/#interface" xmlns:sensor="http://playerstage.sourceforge.net/gazebo/xmlschema/#sensor" xmlns:xacro="http://ros.org/wiki/xacro">
  <!-- Some macros used by the urdf -->
  <!--
     Little helper macro to define the inertia matrix needed
     for links.
     -->
  <!-- length is along the y-axis! -->
  <!-- Directories -->
  <!-- Constants -->
  <!-- Gazebo macros -->
  <!-- Gazebo joint configuration -->
  <!--
     Little helper macro to define the inertia matrix needed
     for links.
     -->
  <!-- length is along the y-axis! -->
  <!-- Not sure about that ... -->
  <!-- right is either 1 (for right arm) or -1 (for left arm) -->
  <material name="DarkGrey">
    <color rgba="0.3 0.3 0.3 1.0"/>
  </material>
  <material name="Black">
    <color rgba="0 0 0 1.0"/>
  </material>
  <material name="Orange">
    <color rgba="1.0 0.487 0 1.0"/>
  </material>
  <material name="Silver">
    <color rgba="1.0 1.0 1.0 1.0"/>
  </material>
  <material name="Grey">
    <color rgba="0.7 0.7 0.7 1.0"/>
  </material>
  <material name="Blue">
    <color rgba="0.0 0.0 0.8 1.0"/>
  </material>
  <material name="HandGray">
    <color rgba="0.953 0.996 0.694 1.0"/>
  </material>
  <material name="SickBlue">
    <color rgba="0.3058 0.5921 0.7294 1.0"/>
  </material>
  <!-- Directories -->
  <!-- Constants -->
  <!-- Gazebo macros -->
  <!-- Gazebo joint configuration -->
  <!--
     Little helper macro to define the inertia matrix needed
     for links.
     -->
  <!-- length is along the y-axis! -->
  <!-- Directories -->
  <!-- Constants -->
  <!-- Gazebo macros -->
  <!-- Gazebo joint configuration -->
  <!--
     Little helper macro to define the inertia matrix needed
     for links.
     -->
  <!-- length is along the y-axis! -->
  <!-- High-leveel hand macro -->
  <!-- Fingers -->
  <!-- Components PALM  -->
  <!-- Components MAIN FINGERS  -->
  <!--DOF 0-->
  <!--DOF 1-->
  <!--DOF 2-->
  <!--DOF 3-->
  <!--DOF 4-->
  <!-- Components THUMB  -->
  <!--DOF 0 THUMB-->
  <!--DOF 1 THUMB-->
  <!--DOF 2 THUMB-->
  <!--DOF 3 THUMB-->
  <!--DOF 4 THUMB-->
  <!-- This plugin outputs the robot's joint positions and inputs joint torques -->
  <gazebo>
    <plugin filename="libmy_robot_plugin.so" name="input_all_torques">
      <topicName>/lwr/input_torques/ </topicName>
      <bodyName>lwr_arm_7_link </bodyName>
    </plugin>
  </gazebo>
  <!-- Sets a joint position (for replay)  -->
  <gazebo>
    <plugin filename="libset_joint_position_plugin.so" name="set_joint_position">
      <topicName>/set_gazebo_joint_states </topicName>
    </plugin>
  </gazebo>
  <!-- Streams the contacts  -->
  <gazebo>
    <plugin filename="libgazebo_ros_my_contact_plugin.so" name="link_collision_sensor">
      <always_on>true</always_on>
      <update_rate>20</update_rate>
      <bumperTopicName>/link_collision_sensor</bumperTopicName>
      <frameName/>
    </plugin>
  </gazebo>
  <!-- Kuka -->
  <joint name="aluplate_lwr_arm_base_joint" type="fixed">
    <origin rpy="0 0 0" xyz="0 0 0"/>
    <parent link="aluplate"/>
    <child link="calib_lwr_arm_base_link"/>
  </joint>
  <link name="calib_lwr_arm_base_link">
    <inertial>
      <mass value="2.0"/>
      <origin rpy="0 0 0" xyz="0 0 0.055"/>
      <inertia ixx="0.00381666666667" ixy="0" ixz="0" iyy="0.0036" iyz="0" izz="0.00381666666667"/>
    </inertial>
    <visual>
      <origin rpy="0 0 0" xyz="0 0 0"/>
      <geometry>
        <mesh filename="package://lwr_description/model/meshes_arm/arm_base.dae"/>
      </geometry>
      <material name="Orange"/>
    </visual>
    <collision>
      <origin rpy="0 0 0" xyz="0 0 0"/>
      <geometry>
        <mesh filename="package://lwr_description/model/meshes_arm/convex/arm_base_convex.stl"/>
      </geometry>
    </collision>
  </link>
  <gazebo reference="calib_lwr_arm_base_link">
    <material value="Gazebo/Orange"/>
  </gazebo>
  <joint name="lwr_arm_0_joint" type="revolute">
    <origin rpy="0 0 0" xyz="0 0 0.11"/>
    <axis xyz="0 0 1"/>
    <limit effort="204" lower="-2.96705972839" upper="2.96705972839" velocity="1.91986217719"/>
    <dynamics damping="0.2" friction="0.0"/>
    <parent link="calib_lwr_arm_base_link"/>
    <child link="lwr_arm_1_link"/>
  </joint>
  <gazebo reference="lwr_arm_0_joint">
    <provideFeedback>true</provideFeedback>
    <implicitSpringDamper>true</implicitSpringDamper>
    <!--<kp>0.0</kp>[> CFM <]-->
    <!--<kd>0.0</kd>[> ERP <]-->
    <!--<cfmDamping>true</cfmDamping>-->
    <!--<dynamics damping="5.5" friction="1"/>-->
  </gazebo>
  <link name="lwr_arm_1_link">
    <inertial>
      <mass value="2.0"/>
      <origin rpy="0 0 0" xyz="0 0.05 0.130"/>
      <inertia ixx="0.0136666666667" ixy="0" ixz="0" iyy="0.0118666666667" iyz="0" izz="0.003"/>
    </inertial>
    <visual>
      <origin rpy="0 0 3.14159265359" xyz="0 0 0"/>
      <geometry>
        <mesh filename="package://lwr_description/model/meshes_arm/arm_segment_a.dae"/>
      </geometry>
      <material name="Orange"/>
    </visual>
    <collision>
      <origin rpy="0 0 3.14159265359" xyz="0 0 0"/>
      <geometry>
        <mesh filename="package://lwr_description/model/meshes_arm/convex/arm_segment_a_convex.stl"/>
      </geometry>
    </collision>
  </link>
  <transmission name="lwr_arm_0_trans">
    <type>transmission_interface/SimpleTransmission</type>
    <joint name="lwr_arm_0_joint">
      <hardwareInterface>EffortJointInterface</hardwareInterface>
    </joint>
    <actuator name="lwr_arm_0_motor">
      <mechanicalReduction>1</mechanicalReduction>
    </actuator>
  </transmission>
  <joint name="lwr_arm_1_joint" type="revolute">
    <origin rpy="0 0 0" xyz="0 0 0.20"/>
    <axis xyz="0 -1 0"/>
    <limit effort="306" lower="-1.91986217719" upper="1.91986217719" velocity="1.91986217719"/>
    <safety_controller k_position="100" k_velocity="2" soft_lower_limit="-2.05948851735" soft_upper_limit="2.05948851735"/>
    <dynamics damping="0.2" friction="0.0"/>
    <parent link="lwr_arm_1_link"/>
    <child link="lwr_arm_2_link"/>
  </joint>
  <gazebo reference="lwr_arm_1_joint">
    <provideFeedback>true</provideFeedback>
    <implicitSpringDamper>true</implicitSpringDamper>
    <!--<kp>0.0</kp>[> CFM <]-->
    <!--<kd>0.0</kd>[> ERP <]-->
    <!--<cfmDamping>true</cfmDamping>-->
    <!--<dynamics damping="5.5" friction="1"/>-->
  </gazebo>
  <link name="lwr_arm_2_link">
    <inertial>
      <mass value="2.0"/>
      <origin rpy="0 0 0" xyz="0 -0.05 0.07"/>
      <!--cuboid_inertia_def length="0.12" width="0.06" height="0.260"
        mass="${arm_elem_link_mass}"/-->
      <inertia ixx="0.0136666666667" ixy="0" ixz="0" iyy="0.0118666666667" iyz="0" izz="0.003"/>
    </inertial>
    <visual>
      <origin rpy="3.14159265359 0 3.14159265359" xyz="0 0 0.2"/>
      <geometry>
        <mesh filename="package://lwr_description/model/meshes_arm/arm_segment_b.dae"/>
      </geometry>
      <material name="Orange"/>
    </visual>
    <collision>
      <origin rpy="3.14159265359 0 3.14159265359" xyz="0 0 0.2"/>
      <geometry>
        <mesh filename="package://lwr_description/model/meshes_arm/convex/arm_segment_b_convex.stl"/>
      </geometry>
    </collision>
  </link>
  <gazebo reference="lwr_arm_2_link">
    <material value="Gazebo/Orange"/>
    <mu1>0.15</mu1>
    <mu2>0.15</mu2>
    <!-- This defines the springiness of the contacts: 400000 -->
    <kp>400000</kp>
    <selfCollide>false</selfCollide>
    <material>Gazebo/Grey</material>
  </gazebo>
  <transmission name="lwr_arm_1_trans">
    <type>transmission_interface/SimpleTransmission</type>
    <actuator name="lwr_arm_1_motor"/>
    <joint name="lwr_arm_1_joint">
      <hardwareInterface>EffortJointInterface</hardwareInterface>
    </joint>
    <mechanicalReduction>1.0</mechanicalReduction>
  </transmission>
  <joint name="lwr_arm_2_joint" type="revolute">
    <origin rpy="0 0 0" xyz="0 0 0.20"/>
    <axis xyz="0 0 1"/>
    <limit effort="204" lower="-2.96705972839" upper="2.96705972839" velocity="2.26892802759"/>
    <!--safety_controller soft_lower_limit="${-168 * M_PI / 180}"
                         soft_upper_limit="${168 * M_PI / 180}"
                         k_position="${safety_controller_k_pos}"
                         k_velocity="${safety_controller_k_vel}"/-->
    <dynamics damping="0.2" friction="0.0"/>
    <parent link="lwr_arm_2_link"/>
    <child link="lwr_arm_3_link"/>
  </joint>
  <gazebo reference="lwr_arm_2_joint">
    <provideFeedback>true</provideFeedback>
    <implicitSpringDamper>true</implicitSpringDamper>
    <!--<kp>0.0</kp>[> CFM <]-->
    <!--<kd>0.0</kd>[> ERP <]-->
    <!--<cfmDamping>true</cfmDamping>-->
    <!--<dynamics damping="5.5" friction="1"/>-->
  </gazebo>
  <link name="lwr_arm_3_link">
    <inertial>
      <mass value="2.0"/>
      <origin rpy="0 0 0" xyz="0 -0.06 0.130"/>
      <inertia ixx="0.0136666666667" ixy="0" ixz="0" iyy="0.0118666666667" iyz="0" izz="0.003"/>
    </inertial>
    <visual>
      <origin rpy="0 0 0" xyz="0 0 0"/>
      <geometry>
        <mesh filename="package://lwr_description/model/meshes_arm/arm_segment_a.dae"/>
      </geometry>
      <material name="Orange"/>
    </visual>
    <collision>
      <origin rpy="0 0 0" xyz="0 0 0"/>
      <geometry>
        <mesh filename="package://lwr_description/model/meshes_arm/convex/arm_segment_a_convex.stl"/>
      </geometry>
    </collision>
  </link>
  <gazebo reference="lwr_arm_3_link">
    <material value="Gazebo/Orange"/>
  </gazebo>
  <!--transmission name="${name}_arm_2_trans" type="transmission_interface/SimpleTransmission">
      <actuator name="${name}_arm_2_motor"/>
      <joint name="${name}_arm_2_joint"/>
      <mechanicalReduction>1.0</mechanicalReduction>
    </transmission-->
  <transmission name="lwr_arm_2_trans">
    <type>transmission_interface/SimpleTransmission</type>
    <actuator name="lwr_arm_2_motor"/>
    <joint name="lwr_arm_2_joint">
      <hardwareInterface>EffortJointInterface</hardwareInterface>
    </joint>
    <mechanicalReduction>1.0</mechanicalReduction>
  </transmission>
  <joint name="lwr_arm_3_joint" type="revolute">
    <origin rpy="0 0 0" xyz="0 0 0.20"/>
    <axis xyz="0 1 0"/>
    <limit effort="306" lower="-2.09439510239" upper="2.09439510239" velocity="2.26892802759"/>
    <safety_controller k_position="100" k_velocity="2" soft_lower_limit="-2.05948851735" soft_upper_limit="2.05948851735"/>
    <dynamics damping="0.2" friction="0.0"/>
    <parent link="lwr_arm_3_link"/>
    <child link="lwr_arm_4_link"/>
  </joint>
  <gazebo reference="lwr_arm_3_joint">
    <provideFeedback>true</provideFeedback>
    <implicitSpringDamper>true</implicitSpringDamper>
    <!--<kp>0.0</kp>[> CFM <]-->
    <!--<kd>0.0</kd>[> ERP <]-->
    <!--<cfmDamping>true</cfmDamping>-->
    <!--<dynamics damping="5.5" friction="1"/>-->
  </gazebo>
  <link name="lwr_arm_4_link">
    <inertial>
      <mass value="2.0"/>
      <origin rpy="0 0 0" xyz="0 0.06 0.07"/>
      <inertia ixx="0.0136666666667" ixy="0" ixz="0" iyy="0.0118666666667" iyz="0" izz="0.003"/>
    </inertial>
    <visual>
      <origin rpy="0 3.14159265359 3.14159265359" xyz="0 0 0.2"/>
      <geometry>
        <mesh filename="package://lwr_description/model/meshes_arm/arm_segment_b.dae"/>
      </geometry>
      <material name="Orange"/>
    </visual>
    <collision>
      <origin rpy="0 3.14159265359 3.14159265359" xyz="0 0 0.2"/>
      <geometry>
        <mesh filename="package://lwr_description/model/meshes_arm/convex/arm_segment_b_convex.stl"/>
      </geometry>
    </collision>
  </link>
  <gazebo reference="lwr_arm_4_link">
    <material value="Gazebo/Orange"/>
    <mu1>0.15</mu1>
    <mu2>0.15</mu2>
    <!-- This defines the springiness of the contacts: 400000 -->
    <kp>400000</kp>
    <selfCollide>false</selfCollide>
    <material>Gazebo/Grey</material>
  </gazebo>
  <transmission name="lwr_arm_3_trans">
    <type>transmission_interface/SimpleTransmission</type>
    <actuator name="lwr_arm_3_motor"/>
    <joint name="lwr_arm_3_joint">
      <hardwareInterface>EffortJointInterface</hardwareInterface>
    </joint>
    <mechanicalReduction>1.0</mechanicalReduction>
  </transmission>
  <joint name="lwr_arm_4_joint" type="revolute">
    <origin rpy="0 0 0" xyz="0 0 0.20"/>
    <axis xyz="0 0 1"/>
    <limit effort="204" lower="-2.96705972839" upper="2.96705972839" velocity="2.26892802759"/>
    <safety_controller k_position="100" k_velocity="2" soft_lower_limit="-2.93215314335" soft_upper_limit="2.93215314335"/>
    <dynamics damping="0.2" friction="0.0"/>
    <parent link="lwr_arm_4_link"/>
    <child link="lwr_arm_5_link"/>
  </joint>
  <gazebo reference="lwr_arm_4_joint">
    <provideFeedback>true</provideFeedback>
    <implicitSpringDamper>true</implicitSpringDamper>
    <!--<kp>0.0</kp>[> CFM <]-->
    <!--<kd>0.0</kd>[> ERP <]-->
    <!--<cfmDamping>true</cfmDamping>-->
    <!--<dynamics damping="5.5" friction="1"/>-->
  </gazebo>
  <link name="lwr_arm_5_link">
    <inertial>
      <mass value="2.0"/>
      <origin rpy="0 0 0" xyz="0 0 0.124"/>
      <inertia ixx="0.0126506666667" ixy="0" ixz="0" iyy="0.0108506666667" iyz="0" izz="0.003"/>
    </inertial>
    <visual>
      <origin rpy="0 0 3.14159265359" xyz="0 0 0"/>
      <geometry name="lwr_arm_5_geom">
        <mesh filename="package://lwr_description/model/meshes_arm/arm_segment_last.dae"/>
      </geometry>
      <material name="Orange"/>
    </visual>
    <collision>
      <origin rpy="0 0 3.14159265359" xyz="0 0 0"/>
      <geometry>
        <mesh filename="package://lwr_description/model/meshes_arm/convex/arm_segment_last_convex.stl"/>
      </geometry>
    </collision>
  </link>
  <gazebo reference="lwr_arm_5_link">
    <material value="Gazebo/Orange"/>
  </gazebo>
  <transmission name="lwr_arm_4_trans">
    <type>transmission_interface/SimpleTransmission</type>
    <actuator name="lwr_arm_4_motor"/>
    <joint name="lwr_arm_4_joint">
      <hardwareInterface>EffortJointInterface</hardwareInterface>
    </joint>
    <mechanicalReduction>1.0</mechanicalReduction>
  </transmission>
  <joint name="lwr_arm_5_joint" type="revolute">
    <origin rpy="0 0 0" xyz="0 0 0.19"/>
    <axis xyz="0 -1 0"/>
    <limit effort="306" lower="-2.09439510239" upper="2.09439510239" velocity="3.14159265359"/>
    <safety_controller k_position="100" k_velocity="2" soft_lower_limit="-2.05948851735" soft_upper_limit="2.05948851735"/>
    <dynamics damping="0.2" friction="0.0"/>
    <parent link="lwr_arm_5_link"/>
    <child link="lwr_arm_6_link"/>
  </joint>
  <gazebo reference="lwr_arm_5_joint">
    <provideFeedback>true</provideFeedback>
    <implicitSpringDamper>true</implicitSpringDamper>
    <!--<kp>0.0</kp>[> CFM <]-->
    <!--<kd>0.0</kd>[> ERP <]-->
    <!--<cfmDamping>true</cfmDamping>-->
    <!--<dynamics damping="5.5" friction="1"/>-->
  </gazebo>
  <link name="lwr_arm_6_link">
    <inertial>
      <mass value="2.0"/>
      <origin rpy="0 0 0" xyz="0 0 0.0"/>
      <inertia ixx="0.00520833333333" ixy="0" ixz="0" iyy="0.00520833333333" iyz="0" izz="0.00520833333333"/>
    </inertial>
    <visual>
      <origin rpy="0 0 3.14159265359" xyz="0 0 0"/>
      <geometry>
        <mesh filename="package://lwr_description/model/meshes_arm/arm_wrist.dae"/>
      </geometry>
      <material name="Grey"/>
    </visual>
    <collision>
      <origin rpy="0 0 3.14159265359" xyz="0 0 0"/>
      <geometry>
        <mesh filename="package://lwr_description/model/meshes_arm/convex/arm_wrist_convex.stl"/>
      </geometry>
    </collision>
  </link>
  <gazebo reference="lwr_arm_6_link">
    <material value="Gazebo/Orange"/>
  </gazebo>
  <transmission name="lwr_arm_5_trans">
    <type>transmission_interface/SimpleTransmission</type>
    <actuator name="lwr_arm_5_motor"/>
    <joint name="lwr_arm_5_joint">
      <hardwareInterface>EffortJointInterface</hardwareInterface>
    </joint>
    <mechanicalReduction>1.0</mechanicalReduction>
  </transmission>
  <joint name="lwr_arm_6_joint" type="revolute">
    <origin rpy="0 0 0" xyz="0 0 0.078"/>
    <axis xyz="0 0 1"/>
    <limit effort="204" lower="-2.96705972839" upper="2.96705972839" velocity="3.14159265359"/>
    <safety_controller k_position="100" k_velocity="2" soft_lower_limit="-2.93215314335" soft_upper_limit="2.93215314335"/>
    <dynamics damping="0.2" friction="0.0"/>
    <parent link="lwr_arm_6_link"/>
    <child link="lwr_arm_7_link"/>
  </joint>
  <gazebo reference="lwr_arm_6_joint">
    <provideFeedback>true</provideFeedback>
    <implicitSpringDamper>true</implicitSpringDamper>
    <!--<kp>0.0</kp>[> CFM <]-->
    <!--<kd>0.0</kd>[> ERP <]-->
    <!--<cfmDamping>true</cfmDamping>-->
    <!--<dynamics damping="5.5" friction="1"/>-->
  </gazebo>
  <link name="lwr_arm_7_link">
    <inertial>
      <mass value="2.0"/>
      <origin xyz="0 0 0"/>
      <inertia ixx="0.000833333333333" ixy="0" ixz="0" iyy="0.000833333333333" iyz="0" izz="0.000833333333333"/>
    </inertial>
    <visual>
      <origin rpy="0 0 2.35619449019" xyz="0 0 0"/>
      <geometry>
        <mesh filename="package://lwr_description/model/meshes_arm/arm_flanche.dae"/>
      </geometry>
      <material name="Grey"/>
    </visual>
    <!--                       <collision>
                        <origin xyz="0 0 0" rpy="0 0 ${right * -1/4 * M_PI  +  M_PI}"/>
                        <geometry>
                          <mesh filename="package://lwr_description/model/meshes_arm/convex/arm_flanche${tool_name}_convex.stl"/>
                        </geometry>
                      </collision> -->
  </link>
  <!-- Do not load the plugin: this is now done on the other side .. -->
  <!-- <gazebo>
  <plugin name="mylinkforce2" filename="libgazebo_ros_force2.so">
     <topicName> /spacenav/twist/ </topicName>    
    <bodyName> lwr_arm_7_link </bodyName>
  </plugin>
</gazebo> -->
  <link name="lwr_arm_hand_link"/>
  <gazebo reference="lwr_arm_7_link">
    <material value="Gazebo/Grey"/>
  </gazebo>
  <transmission name="lwr_arm_6_trans">
    <type>transmission_interface/SimpleTransmission</type>
    <actuator name="lwr_arm_6_motor"/>
    <joint name="lwr_arm_6_joint">
      <hardwareInterface>EffortJointInterface</hardwareInterface>
    </joint>
    <mechanicalReduction>1.0</mechanicalReduction>
  </transmission>
  <joint name="lwr_arm_hand_fixed_joint" type="fixed">
    <origin rpy="1.57079632679 0 5.49778714378" xyz="-0.075 -0.075 -0.094"/>
    <parent link="lwr_arm_7_link"/>
    <child link="lwr_arm_hand_link"/>
  </joint>
  <gazebo reference="lwr_arm_7_joint">
    <provideFeedback>true</provideFeedback>
    <implicitSpringDamper>true</implicitSpringDamper>
    <!--<kp>0.0</kp>[> CFM <]-->
    <!--<kd>0.0</kd>[> ERP <]-->
    <!--<cfmDamping>true</cfmDamping>-->
    <!--<dynamics damping="5.5" friction="1"/>-->
  </gazebo>
  <!-- AluPlate -->
  <joint name="world_joint2" type="fixed">
    <origin rpy="0 0 0" xyz="0.0 0.0 0.03"/>
    <parent link="world"/>
    <child link="aluplate"/>
  </joint>
  <link name="aluplate">
    <visual>
      <origin xyz="0 0 0.01"/>
      <geometry>
        <box size="0.2 0.2 0.02" xyz="0.0 0.0 0.0"/>
      </geometry>
      <material name="Silver"/>
    </visual>
    <collision name="aluplate_collision">
      <geometry>
        <box size="0.2 0.2 0.02" xyz="0.0 0.0 0.0"/>
      </geometry>
    </collision>
  </link>
  <gazebo reference="aluplate">
    <material value="Gazebo/Grey"/>
  </gazebo>
  <link name="world"/>
  <!-- Hand -->
  <joint name="ahand/ahand_base_joint" type="fixed">
    <parent link="lwr_arm_7_link"/>
    <child link="ahand/ahand_palm_link"/>
    <origin rpy="0 0 0" xyz="0 0 0.1"/>
  </joint>
  <gazebo reference="ahand/ahand_palm_link">
    <mu1>0.15</mu1>
    <mu2>0.15</mu2>
    <!-- This defines the springiness of the contacts: 400000 -->
    <kp>400000</kp>
    <selfCollide>false</selfCollide>
    <material>Gazebo/Grey</material>
  </gazebo>
  <link name="ahand/ahand_palm_link">
    <inertial>
      <origin xyz="-0.01 0 -0.05"/>
      <inertia ixx="0.00184605916667" ixy="0" ixz="0" iyy="0.00112558666667" iyz="0" izz="0.00103097916667"/>
      <mass value="1.1644"/>
    </inertial>
    <visual>
      <origin rpy="3.14159265359 0 0" xyz="-0.0282 0.057 -0.095"/>
      <geometry>
        <mesh filename="package://allegro_hand_description_nico/models/shapes/allegro_palm_right.dae"/>
      </geometry>
    </visual>
    <collision>
      <origin rpy="0.0 0 0.0" xyz="-0.008 0  -0.025"/>
      <geometry>
        <box size="0.04 0.1 0.04"/>
      </geometry>
    </collision>
  </link>
  <joint name="ahand/finger_1/dof0_joint" type="revolute">
    <parent link="ahand/ahand_palm_link"/>
    <child link="ahand/finger_1/dof0_link"/>
    <origin rpy="-0.0873 0 0" xyz="0 0.044981 -0.002298"/>
    <axis xyz="0 0 1"/>
    <limit effort="100" lower="-0.469999993522" upper="0.469999993522" velocity="100"/>
    <dynamics damping="0.005" friction="0.0"/>
  </joint>
  <gazebo reference="ahand/finger_1/dof0_joint">
    <provideFeedback>true</provideFeedback>
    <implicitSpringDamper>true</implicitSpringDamper>
    <!--<kp>0.0</kp>[> CFM <]-->
    <!--<kd>0.0</kd>[> ERP <]-->
    <!--<cfmDamping>true</cfmDamping>-->
    <!--<dynamics damping="5.5" friction="1"/>-->
  </gazebo>
  <gazebo reference="ahand/finger_1/dof0_link">
    <mu1>0.15</mu1>
    <mu2>0.15</mu2>
    <!-- This defines the springiness of the contacts: 400000 -->
    <kp>400000</kp>
    <selfCollide>false</selfCollide>
    <material>Gazebo/Grey</material>
  </gazebo>
  <link name="ahand/finger_1/dof0_link">
    <inertial>
      <origin xyz="0.00 0 0.01"/>
      <inertia ixx="9.39583333333e-07" ixy="0" ixz="0" iyy="1.14583333333e-06" iyz="0" izz="9.39583333333e-07"/>
      <mass value="0.0119"/>
    </inertial>
    <visual>
      <material name="black">
        <color rgba="0.2 0.2 0.2 1"/>
      </material>
      <geometry>
        <mesh filename="package://allegro_hand_description/meshes/link_0.0.STL"/>
      </geometry>
    </visual>
    <collision>
      <origin rpy="0.0 0 0.0" xyz=" 0 0 0.01 "/>
      <geometry>
        <cylinder length="0.02" radius="0.0115"/>
      </geometry>
    </collision>
  </link>
  <joint name="ahand/finger_1/dof1_joint" type="revolute">
    <parent link="ahand/finger_1/dof0_link"/>
    <child link="ahand/finger_1/dof1_link"/>
    <origin rpy="-1.57079632679 0 0" xyz="0 0 0.0164"/>
    <axis xyz="0 0 1"/>
    <limit effort="100" lower="-0.19600000376" upper="1.60999999972" velocity="100"/>
    <dynamics damping="0.005" friction="0.0"/>
  </joint>
  <gazebo reference="ahand/finger_1/dof1_joint">
    <provideFeedback>true</provideFeedback>
    <implicitSpringDamper>true</implicitSpringDamper>
    <!--<kp>0.0</kp>[> CFM <]-->
    <!--<kd>0.0</kd>[> ERP <]-->
    <!--<cfmDamping>true</cfmDamping>-->
    <!--<dynamics damping="5.5" friction="1"/>-->
  </gazebo>
  <gazebo reference="ahand/finger_1/dof1_link">
    <mu1>0.15</mu1>
    <mu2>0.15</mu2>
    <!-- This defines the springiness of the contacts: 400000 -->
    <kp>400000</kp>
    <selfCollide>false</selfCollide>
    <material>Gazebo/Grey</material>
  </gazebo>
  <link name="ahand/finger_1/dof1_link">
    <inertial>
      <origin xyz="0.  -0.027 0 "/>
      <inertia ixx="2.01246833333e-05" ixy="0" ixz="0" iyy="7.10416666667e-06" iyz="0" izz="2.01246833333e-05"/>
      <mass value="0.065"/>
    </inertial>
    <visual>
      <origin rpy="1.57079632679 0.0 0.0" xyz="0.0 0.0 0.0"/>
      <geometry>
        <mesh filename="package://allegro_hand_description/meshes/link_1.0.STL"/>
      </geometry>
      <material name="black"/>
    </visual>
    <collision>
      <origin rpy="1.57079632679 0 0.0" xyz=" 0.  -0.027 0  "/>
      <geometry>
        <cylinder length="0.035" radius="0.0125"/>
      </geometry>
    </collision>
  </link>
  <joint name="ahand/finger_1/dof2_joint" type="revolute">
    <parent link="ahand/finger_1/dof1_link"/>
    <child link="ahand/finger_1/dof2_link"/>
    <origin rpy="0 0 -1.57079632679" xyz="0.0 -0.054 0.0"/>
    <axis xyz="0 0 1"/>
    <limit effort="100" lower="-0.174000006366" upper="1.70899999672" velocity="100"/>
    <dynamics damping="0.005" friction="0.0"/>
  </joint>
  <gazebo reference="ahand/finger_1/dof2_joint">
    <provideFeedback>true</provideFeedback>
    <implicitSpringDamper>true</implicitSpringDamper>
    <!--<kp>0.0</kp>[> CFM <]-->
    <!--<kd>0.0</kd>[> ERP <]-->
    <!--<cfmDamping>true</cfmDamping>-->
    <!--<dynamics damping="5.5" friction="1"/>-->
  </gazebo>
  <gazebo reference="ahand/finger_1/dof2_link">
    <mu1>0.15</mu1>
    <mu2>0.15</mu2>
    <!-- This defines the springiness of the contacts: 400000 -->
    <kp>400000</kp>
    <selfCollide>true</selfCollide>
    <material>Gazebo/Grey</material>
  </gazebo>
  <link name="ahand/finger_1/dof2_link">
    <inertial>
      <origin xyz=" 0.0192 0 0 "/>
      <inertia ixx="4.1875e-06" ixy="0" ixz="0" iyy="7.033526e-06" iyz="0" izz="7.033526e-06"/>
      <mass value="0.0355"/>
    </inertial>
    <visual>
      <origin rpy="1.57079632679 0 1.57079632679" xyz="-0.0 -0.0 -0.0"/>
      <geometry>
        <mesh filename="package://allegro_hand_description/meshes/link_2.0.STL"/>
      </geometry>
      <material name="black"/>
    </visual>
    <collision>
      <origin rpy="1.57079632679 0 1.57079632679" xyz=" 0.022 0 0 "/>
      <geometry>
        <cylinder length="0.05" radius="0.0115"/>
      </geometry>
    </collision>
  </link>
  <joint name="ahand/finger_1/dof3_joint" type="revolute">
    <parent link="ahand/finger_1/dof2_link"/>
    <child link="ahand/finger_1/dof3_link"/>
    <origin rpy="0 0 0" xyz="0.0384 0 0"/>
    <axis xyz="0 0 1"/>
    <limit effort="100" lower="-0.227000000882" upper="1.6179999956" velocity="100"/>
    <dynamics damping="0.005" friction="0.0"/>
  </joint>
  <gazebo reference="ahand/finger_1/dof3_joint">
    <provideFeedback>true</provideFeedback>
    <implicitSpringDamper>true</implicitSpringDamper>
    <!--<kp>0.0</kp>[> CFM <]-->
    <!--<kd>0.0</kd>[> ERP <]-->
    <!--<cfmDamping>true</cfmDamping>-->
    <!--<dynamics damping="5.5" friction="1"/>-->
  </gazebo>
  <gazebo reference="ahand/finger_1/dof3_link">
    <mu1>0.15</mu1>
    <mu2>0.15</mu2>
    <!-- This defines the springiness of the contacts: 400000 -->
    <kp>400000</kp>
    <selfCollide>true</selfCollide>
    <material>Gazebo/Grey</material>
  </gazebo>
  <link name="ahand/finger_1/dof3_link">
    <inertial>
      <origin xyz=" 0.01 0 0 "/>
      <inertia ixx="9.79166666667e-07" ixy="0" ixz="0" iyy="8.02916666667e-07" iyz="0" izz="8.02916666667e-07"/>
      <mass value="0.0096"/>
    </inertial>
    <visual>
      <origin rpy="1.57079632679 0 1.57079632679" xyz=" 0.0 0 0 "/>
      <material name="black"/>
      <geometry>
        <mesh filename="package://allegro_hand_description/meshes/link_3.0.STL"/>
      </geometry>
    </visual>
  </link>
  <joint name="ahand/finger_1/dof4_joint" type="fixed">
    <parent link="ahand/finger_1/dof3_link"/>
    <child link="ahand/finger_1/dof4_link"/>
    <origin rpy="0 0 0" xyz="0.016 0 0"/>
  </joint>
  <link name="ahand/finger_1/dof4_link">
    <inertial>
      <origin xyz=" 0.01 0 0 "/>
      <inertia ixx="1.17333333333e-06" ixy="0" ixz="0" iyy="1.17333333333e-06" iyz="0" izz="1.17333333333e-06"/>
      <mass value="0.0168"/>
    </inertial>
    <gazebo reference="ahand/finger_1/dof3_link">
      <mu1>0.15</mu1>
      <mu2>0.15</mu2>
      <!-- This defines the springiness of the contacts: 400000 -->
      <kp>400000</kp>
      <selfCollide>true</selfCollide>
      <material>Gazebo/Grey</material>
      <material>Gazebo/White</material>
    </gazebo>
    <visual>
      <origin rpy="1.57079632679 0 1.57079632679" xyz=" 0.01 0 0 "/>
      <geometry>
        <mesh filename="package://allegro_hand_description/meshes/link_3.0_tip.STL"/>
      </geometry>
      <material name="white">
        <color rgba=".9 .9 .9 1"/>
      </material>
    </visual>
    <collision name="ahand/finger_1/dof4_link_collision">
      <origin rpy="0 0 -1.57079632679" xyz=" 0.01 0 0 "/>
      <geometry>
        <sphere radius="0.01"/>
      </geometry>
    </collision>
  </link>
  <joint name="ahand/finger_2/dof0_joint" type="revolute">
    <parent link="ahand/ahand_palm_link"/>
    <child link="ahand/finger_2/dof0_link"/>
    <origin rpy="0 0 0.0" xyz="0 0 0"/>
    <axis xyz="0 0 1"/>
    <limit effort="100" lower="-0.469999993522" upper="0.469999993522" velocity="100"/>
    <dynamics damping="0.005" friction="0.0"/>
  </joint>
  <gazebo reference="ahand/finger_2/dof0_joint">
    <provideFeedback>true</provideFeedback>
    <implicitSpringDamper>true</implicitSpringDamper>
    <!--<kp>0.0</kp>[> CFM <]-->
    <!--<kd>0.0</kd>[> ERP <]-->
    <!--<cfmDamping>true</cfmDamping>-->
    <!--<dynamics damping="5.5" friction="1"/>-->
  </gazebo>
  <gazebo reference="ahand/finger_2/dof0_link">
    <mu1>0.15</mu1>
    <mu2>0.15</mu2>
    <!-- This defines the springiness of the contacts: 400000 -->
    <kp>400000</kp>
    <selfCollide>false</selfCollide>
    <material>Gazebo/Grey</material>
  </gazebo>
  <link name="ahand/finger_2/dof0_link">
    <inertial>
      <origin xyz="0.00 0 0.01"/>
      <inertia ixx="9.39583333333e-07" ixy="0" ixz="0" iyy="1.14583333333e-06" iyz="0" izz="9.39583333333e-07"/>
      <mass value="0.0119"/>
    </inertial>
    <visual>
      <material name="black">
        <color rgba="0.2 0.2 0.2 1"/>
      </material>
      <geometry>
        <mesh filename="package://allegro_hand_description/meshes/link_0.0.STL"/>
      </geometry>
    </visual>
    <collision>
      <origin rpy="0.0 0 0.0" xyz=" 0 0 0.01 "/>
      <geometry>
        <cylinder length="0.02" radius="0.0115"/>
      </geometry>
    </collision>
  </link>
  <joint name="ahand/finger_2/dof1_joint" type="revolute">
    <parent link="ahand/finger_2/dof0_link"/>
    <child link="ahand/finger_2/dof1_link"/>
    <origin rpy="-1.57079632679 0 0" xyz="0 0 0.0164"/>
    <axis xyz="0 0 1"/>
    <limit effort="100" lower="-0.19600000376" upper="1.60999999972" velocity="100"/>
    <dynamics damping="0.005" friction="0.0"/>
  </joint>
  <gazebo reference="ahand/finger_2/dof1_joint">
    <provideFeedback>true</provideFeedback>
    <implicitSpringDamper>true</implicitSpringDamper>
    <!--<kp>0.0</kp>[> CFM <]-->
    <!--<kd>0.0</kd>[> ERP <]-->
    <!--<cfmDamping>true</cfmDamping>-->
    <!--<dynamics damping="5.5" friction="1"/>-->
  </gazebo>
  <gazebo reference="ahand/finger_2/dof1_link">
    <mu1>0.15</mu1>
    <mu2>0.15</mu2>
    <!-- This defines the springiness of the contacts: 400000 -->
    <kp>400000</kp>
    <selfCollide>false</selfCollide>
    <material>Gazebo/Grey</material>
  </gazebo>
  <link name="ahand/finger_2/dof1_link">
    <inertial>
      <origin xyz="0.  -0.027 0 "/>
      <inertia ixx="2.01246833333e-05" ixy="0" ixz="0" iyy="7.10416666667e-06" iyz="0" izz="2.01246833333e-05"/>
      <mass value="0.065"/>
    </inertial>
    <visual>
      <origin rpy="1.57079632679 0.0 0.0" xyz="0.0 0.0 0.0"/>
      <geometry>
        <mesh filename="package://allegro_hand_description/meshes/link_1.0.STL"/>
      </geometry>
      <material name="black"/>
    </visual>
    <collision>
      <origin rpy="1.57079632679 0 0.0" xyz=" 0.  -0.027 0  "/>
      <geometry>
        <cylinder length="0.035" radius="0.0125"/>
      </geometry>
    </collision>
  </link>
  <joint name="ahand/finger_2/dof2_joint" type="revolute">
    <parent link="ahand/finger_2/dof1_link"/>
    <child link="ahand/finger_2/dof2_link"/>
    <origin rpy="0 0 -1.57079632679" xyz="0.0 -0.054 0.0"/>
    <axis xyz="0 0 1"/>
    <limit effort="100" lower="-0.174000006366" upper="1.70899999672" velocity="100"/>
    <dynamics damping="0.005" friction="0.0"/>
  </joint>
  <gazebo reference="ahand/finger_2/dof2_joint">
    <provideFeedback>true</provideFeedback>
    <implicitSpringDamper>true</implicitSpringDamper>
    <!--<kp>0.0</kp>[> CFM <]-->
    <!--<kd>0.0</kd>[> ERP <]-->
    <!--<cfmDamping>true</cfmDamping>-->
    <!--<dynamics damping="5.5" friction="1"/>-->
  </gazebo>
  <gazebo reference="ahand/finger_2/dof2_link">
    <mu1>0.15</mu1>
    <mu2>0.15</mu2>
    <!-- This defines the springiness of the contacts: 400000 -->
    <kp>400000</kp>
    <selfCollide>true</selfCollide>
    <material>Gazebo/Grey</material>
  </gazebo>
  <link name="ahand/finger_2/dof2_link">
    <inertial>
      <origin xyz=" 0.0192 0 0 "/>
      <inertia ixx="4.1875e-06" ixy="0" ixz="0" iyy="7.033526e-06" iyz="0" izz="7.033526e-06"/>
      <mass value="0.0355"/>
    </inertial>
    <visual>
      <origin rpy="1.57079632679 0 1.57079632679" xyz="-0.0 -0.0 -0.0"/>
      <geometry>
        <mesh filename="package://allegro_hand_description/meshes/link_2.0.STL"/>
      </geometry>
      <material name="black"/>
    </visual>
    <collision>
      <origin rpy="1.57079632679 0 1.57079632679" xyz=" 0.022 0 0 "/>
      <geometry>
        <cylinder length="0.05" radius="0.0115"/>
      </geometry>
    </collision>
  </link>
  <joint name="ahand/finger_2/dof3_joint" type="revolute">
    <parent link="ahand/finger_2/dof2_link"/>
    <child link="ahand/finger_2/dof3_link"/>
    <origin rpy="0 0 0" xyz="0.0384 0 0"/>
    <axis xyz="0 0 1"/>
    <limit effort="100" lower="-0.227000000882" upper="1.6179999956" velocity="100"/>
    <dynamics damping="0.005" friction="0.0"/>
  </joint>
  <gazebo reference="ahand/finger_2/dof3_joint">
    <provideFeedback>true</provideFeedback>
    <implicitSpringDamper>true</implicitSpringDamper>
    <!--<kp>0.0</kp>[> CFM <]-->
    <!--<kd>0.0</kd>[> ERP <]-->
    <!--<cfmDamping>true</cfmDamping>-->
    <!--<dynamics damping="5.5" friction="1"/>-->
  </gazebo>
  <gazebo reference="ahand/finger_2/dof3_link">
    <mu1>0.15</mu1>
    <mu2>0.15</mu2>
    <!-- This defines the springiness of the contacts: 400000 -->
    <kp>400000</kp>
    <selfCollide>true</selfCollide>
    <material>Gazebo/Grey</material>
  </gazebo>
  <link name="ahand/finger_2/dof3_link">
    <inertial>
      <origin xyz=" 0.01 0 0 "/>
      <inertia ixx="9.79166666667e-07" ixy="0" ixz="0" iyy="8.02916666667e-07" iyz="0" izz="8.02916666667e-07"/>
      <mass value="0.0096"/>
    </inertial>
    <visual>
      <origin rpy="1.57079632679 0 1.57079632679" xyz=" 0.0 0 0 "/>
      <material name="black"/>
      <geometry>
        <mesh filename="package://allegro_hand_description/meshes/link_3.0.STL"/>
      </geometry>
    </visual>
  </link>
  <joint name="ahand/finger_2/dof4_joint" type="fixed">
    <parent link="ahand/finger_2/dof3_link"/>
    <child link="ahand/finger_2/dof4_link"/>
    <origin rpy="0 0 0" xyz="0.016 0 0"/>
  </joint>
  <link name="ahand/finger_2/dof4_link">
    <inertial>
      <origin xyz=" 0.01 0 0 "/>
      <inertia ixx="1.17333333333e-06" ixy="0" ixz="0" iyy="1.17333333333e-06" iyz="0" izz="1.17333333333e-06"/>
      <mass value="0.0168"/>
    </inertial>
    <gazebo reference="ahand/finger_2/dof3_link">
      <mu1>0.15</mu1>
      <mu2>0.15</mu2>
      <!-- This defines the springiness of the contacts: 400000 -->
      <kp>400000</kp>
      <selfCollide>true</selfCollide>
      <material>Gazebo/Grey</material>
      <material>Gazebo/White</material>
    </gazebo>
    <visual>
      <origin rpy="1.57079632679 0 1.57079632679" xyz=" 0.01 0 0 "/>
      <geometry>
        <mesh filename="package://allegro_hand_description/meshes/link_3.0_tip.STL"/>
      </geometry>
      <material name="white">
        <color rgba=".9 .9 .9 1"/>
      </material>
    </visual>
    <collision name="ahand/finger_2/dof4_link_collision">
      <origin rpy="0 0 -1.57079632679" xyz=" 0.01 0 0 "/>
      <geometry>
        <sphere radius="0.01"/>
      </geometry>
    </collision>
  </link>
  <joint name="ahand/finger_3/dof0_joint" type="revolute">
    <parent link="ahand/ahand_palm_link"/>
    <child link="ahand/finger_3/dof0_link"/>
    <origin rpy="0.0873 0 -0.0" xyz="0 -0.044981 -0.002298"/>
    <axis xyz="0 0 1"/>
    <limit effort="100" lower="-0.469999993522" upper="0.469999993522" velocity="100"/>
    <dynamics damping="0.005" friction="0.0"/>
  </joint>
  <gazebo reference="ahand/finger_3/dof0_joint">
    <provideFeedback>true</provideFeedback>
    <implicitSpringDamper>true</implicitSpringDamper>
    <!--<kp>0.0</kp>[> CFM <]-->
    <!--<kd>0.0</kd>[> ERP <]-->
    <!--<cfmDamping>true</cfmDamping>-->
    <!--<dynamics damping="5.5" friction="1"/>-->
  </gazebo>
  <gazebo reference="ahand/finger_3/dof0_link">
    <mu1>0.15</mu1>
    <mu2>0.15</mu2>
    <!-- This defines the springiness of the contacts: 400000 -->
    <kp>400000</kp>
    <selfCollide>false</selfCollide>
    <material>Gazebo/Grey</material>
  </gazebo>
  <link name="ahand/finger_3/dof0_link">
    <inertial>
      <origin xyz="0.00 0 0.01"/>
      <inertia ixx="9.39583333333e-07" ixy="0" ixz="0" iyy="1.14583333333e-06" iyz="0" izz="9.39583333333e-07"/>
      <mass value="0.0119"/>
    </inertial>
    <visual>
      <material name="black">
        <color rgba="0.2 0.2 0.2 1"/>
      </material>
      <geometry>
        <mesh filename="package://allegro_hand_description/meshes/link_0.0.STL"/>
      </geometry>
    </visual>
    <collision>
      <origin rpy="0.0 0 0.0" xyz=" 0 0 0.01 "/>
      <geometry>
        <cylinder length="0.02" radius="0.0115"/>
      </geometry>
    </collision>
  </link>
  <joint name="ahand/finger_3/dof1_joint" type="revolute">
    <parent link="ahand/finger_3/dof0_link"/>
    <child link="ahand/finger_3/dof1_link"/>
    <origin rpy="-1.57079632679 0 0" xyz="0 0 0.0164"/>
    <axis xyz="0 0 1"/>
    <limit effort="100" lower="-0.19600000376" upper="1.60999999972" velocity="100"/>
    <dynamics damping="0.005" friction="0.0"/>
  </joint>
  <gazebo reference="ahand/finger_3/dof1_joint">
    <provideFeedback>true</provideFeedback>
    <implicitSpringDamper>true</implicitSpringDamper>
    <!--<kp>0.0</kp>[> CFM <]-->
    <!--<kd>0.0</kd>[> ERP <]-->
    <!--<cfmDamping>true</cfmDamping>-->
    <!--<dynamics damping="5.5" friction="1"/>-->
  </gazebo>
  <gazebo reference="ahand/finger_3/dof1_link">
    <mu1>0.15</mu1>
    <mu2>0.15</mu2>
    <!-- This defines the springiness of the contacts: 400000 -->
    <kp>400000</kp>
    <selfCollide>false</selfCollide>
    <material>Gazebo/Grey</material>
  </gazebo>
  <link name="ahand/finger_3/dof1_link">
    <inertial>
      <origin xyz="0.  -0.027 0 "/>
      <inertia ixx="2.01246833333e-05" ixy="0" ixz="0" iyy="7.10416666667e-06" iyz="0" izz="2.01246833333e-05"/>
      <mass value="0.065"/>
    </inertial>
    <visual>
      <origin rpy="1.57079632679 0.0 0.0" xyz="0.0 0.0 0.0"/>
      <geometry>
        <mesh filename="package://allegro_hand_description/meshes/link_1.0.STL"/>
      </geometry>
      <material name="black"/>
    </visual>
    <collision>
      <origin rpy="1.57079632679 0 0.0" xyz=" 0.  -0.027 0  "/>
      <geometry>
        <cylinder length="0.035" radius="0.0125"/>
      </geometry>
    </collision>
  </link>
  <joint name="ahand/finger_3/dof2_joint" type="revolute">
    <parent link="ahand/finger_3/dof1_link"/>
    <child link="ahand/finger_3/dof2_link"/>
    <origin rpy="0 0 -1.57079632679" xyz="0.0 -0.054 0.0"/>
    <axis xyz="0 0 1"/>
    <limit effort="100" lower="-0.174000006366" upper="1.70899999672" velocity="100"/>
    <dynamics damping="0.005" friction="0.0"/>
  </joint>
  <gazebo reference="ahand/finger_3/dof2_joint">
    <provideFeedback>true</provideFeedback>
    <implicitSpringDamper>true</implicitSpringDamper>
    <!--<kp>0.0</kp>[> CFM <]-->
    <!--<kd>0.0</kd>[> ERP <]-->
    <!--<cfmDamping>true</cfmDamping>-->
    <!--<dynamics damping="5.5" friction="1"/>-->
  </gazebo>
  <gazebo reference="ahand/finger_3/dof2_link">
    <mu1>0.15</mu1>
    <mu2>0.15</mu2>
    <!-- This defines the springiness of the contacts: 400000 -->
    <kp>400000</kp>
    <selfCollide>true</selfCollide>
    <material>Gazebo/Grey</material>
  </gazebo>
  <link name="ahand/finger_3/dof2_link">
    <inertial>
      <origin xyz=" 0.0192 0 0 "/>
      <inertia ixx="4.1875e-06" ixy="0" ixz="0" iyy="7.033526e-06" iyz="0" izz="7.033526e-06"/>
      <mass value="0.0355"/>
    </inertial>
    <visual>
      <origin rpy="1.57079632679 0 1.57079632679" xyz="-0.0 -0.0 -0.0"/>
      <geometry>
        <mesh filename="package://allegro_hand_description/meshes/link_2.0.STL"/>
      </geometry>
      <material name="black"/>
    </visual>
    <collision>
      <origin rpy="1.57079632679 0 1.57079632679" xyz=" 0.022 0 0 "/>
      <geometry>
        <cylinder length="0.05" radius="0.0115"/>
      </geometry>
    </collision>
  </link>
  <joint name="ahand/finger_3/dof3_joint" type="revolute">
    <parent link="ahand/finger_3/dof2_link"/>
    <child link="ahand/finger_3/dof3_link"/>
    <origin rpy="0 0 0" xyz="0.0384 0 0"/>
    <axis xyz="0 0 1"/>
    <limit effort="100" lower="-0.227000000882" upper="1.6179999956" velocity="100"/>
    <dynamics damping="0.005" friction="0.0"/>
  </joint>
  <gazebo reference="ahand/finger_3/dof3_joint">
    <provideFeedback>true</provideFeedback>
    <implicitSpringDamper>true</implicitSpringDamper>
    <!--<kp>0.0</kp>[> CFM <]-->
    <!--<kd>0.0</kd>[> ERP <]-->
    <!--<cfmDamping>true</cfmDamping>-->
    <!--<dynamics damping="5.5" friction="1"/>-->
  </gazebo>
  <gazebo reference="ahand/finger_3/dof3_link">
    <mu1>0.15</mu1>
    <mu2>0.15</mu2>
    <!-- This defines the springiness of the contacts: 400000 -->
    <kp>400000</kp>
    <selfCollide>true</selfCollide>
    <material>Gazebo/Grey</material>
  </gazebo>
  <link name="ahand/finger_3/dof3_link">
    <inertial>
      <origin xyz=" 0.01 0 0 "/>
      <inertia ixx="9.79166666667e-07" ixy="0" ixz="0" iyy="8.02916666667e-07" iyz="0" izz="8.02916666667e-07"/>
      <mass value="0.0096"/>
    </inertial>
    <visual>
      <origin rpy="1.57079632679 0 1.57079632679" xyz=" 0.0 0 0 "/>
      <material name="black"/>
      <geometry>
        <mesh filename="package://allegro_hand_description/meshes/link_3.0.STL"/>
      </geometry>
    </visual>
  </link>
  <joint name="ahand/finger_3/dof4_joint" type="fixed">
    <parent link="ahand/finger_3/dof3_link"/>
    <child link="ahand/finger_3/dof4_link"/>
    <origin rpy="0 0 0" xyz="0.016 0 0"/>
  </joint>
  <link name="ahand/finger_3/dof4_link">
    <inertial>
      <origin xyz=" 0.01 0 0 "/>
      <inertia ixx="1.17333333333e-06" ixy="0" ixz="0" iyy="1.17333333333e-06" iyz="0" izz="1.17333333333e-06"/>
      <mass value="0.0168"/>
    </inertial>
    <gazebo reference="ahand/finger_3/dof3_link">
      <mu1>0.15</mu1>
      <mu2>0.15</mu2>
      <!-- This defines the springiness of the contacts: 400000 -->
      <kp>400000</kp>
      <selfCollide>true</selfCollide>
      <material>Gazebo/Grey</material>
      <material>Gazebo/White</material>
    </gazebo>
    <visual>
      <origin rpy="1.57079632679 0 1.57079632679" xyz=" 0.01 0 0 "/>
      <geometry>
        <mesh filename="package://allegro_hand_description/meshes/link_3.0_tip.STL"/>
      </geometry>
      <material name="white">
        <color rgba=".9 .9 .9 1"/>
      </material>
    </visual>
    <collision name="ahand/finger_3/dof4_link_collision">
      <origin rpy="0 0 -1.57079632679" xyz=" 0.01 0 0 "/>
      <geometry>
        <sphere radius="0.01"/>
      </geometry>
    </collision>
  </link>
  <joint name="ahand/thumb/dof0_joint" type="revolute">
    <parent link="ahand/ahand_palm_link"/>
    <child link="ahand/thumb/dof0_link"/>
    <origin rpy="-3.0543 0 -3.14159265359" xyz="-0.0182 0.0168753 -0.07308"/>
    <axis xyz="0 0 1"/>
    <limit effort="100" lower="-0.0174532925199" upper="1.4835298642" velocity="100"/>
    <!-- new version, it still needs to be negative ... -->
    <dynamics damping="0.005" friction="0.0"/>
  </joint>
  <gazebo reference="ahand/thumb/dof0_joint">
    <provideFeedback>true</provideFeedback>
    <implicitSpringDamper>true</implicitSpringDamper>
    <!--<kp>0.0</kp>[> CFM <]-->
    <!--<kd>0.0</kd>[> ERP <]-->
    <!--<cfmDamping>true</cfmDamping>-->
    <!--<dynamics damping="5.5" friction="1"/>-->
  </gazebo>
  <gazebo reference="ahand/thumb/dof0_link">
    <mu1>0.15</mu1>
    <mu2>0.15</mu2>
    <!-- This defines the springiness of the contacts: 400000 -->
    <kp>400000</kp>
    <selfCollide>false</selfCollide>
    <material>Gazebo/Grey</material>
  </gazebo>
  <link name="ahand/thumb/dof0_link">
    <inertial>
      <origin xyz="-0.0025 0.02 -0.01 "/>
      <inertia ixx="2.4e-05" ixy="0" ixz="0" iyy="1.5e-05" iyz="0" izz="1.5e-05"/>
      <mass value="0.090"/>
    </inertial>
    <visual>
      <material name="black"/>
      <origin rpy="0.0 1.57079632679 1.57079632679 " xyz="0.0 -0.0 -0.025"/>
      <geometry>
        <mesh filename="package://allegro_hand_description/meshes/link_12.0_right.STL"/>
      </geometry>
    </visual>
  </link>
  <joint name="ahand/thumb/dof1_joint" type="revolute">
    <parent link="ahand/thumb/dof0_link"/>
    <child link="ahand/thumb/dof1_link"/>
    <origin rpy="-1.57079632679 0.0 0.0" xyz="0 0.0375 -0.0034"/>
    <axis xyz="0 0 1"/>
    <limit effort="100" lower="-0.174532925199" upper="1.25663706144" velocity="100"/>
    <dynamics damping="0.005" friction="0.0"/>
  </joint>
  <gazebo reference="ahand/thumb/dof1_joint">
    <provideFeedback>true</provideFeedback>
    <implicitSpringDamper>true</implicitSpringDamper>
    <!--<kp>0.0</kp>[> CFM <]-->
    <!--<kd>0.0</kd>[> ERP <]-->
    <!--<cfmDamping>true</cfmDamping>-->
    <!--<dynamics damping="5.5" friction="1"/>-->
  </gazebo>
  <gazebo reference="ahand/thumb/dof1_link">
    <mu1>0.15</mu1>
    <mu2>0.15</mu2>
    <!-- This defines the springiness of the contacts: 400000 -->
    <kp>400000</kp>
    <selfCollide>false</selfCollide>
    <material>Gazebo/Grey</material>
  </gazebo>
  <link name="ahand/thumb/dof1_link">
    <inertial>
      <origin xyz="0.00 0.00 0.015 "/>
      <inertia ixx="7.46666666667e-07" ixy="0" ixz="0" iyy="7.46666666667e-07" iyz="0" izz="7.46666666667e-07"/>
      <mass value="0.0112"/>
    </inertial>
    <visual>
      <material name="black"/>
      <origin rpy="0.0 0.0 1.57079632679" xyz="0.0 0.0 0.0"/>
      <geometry>
        <mesh filename="package://allegro_hand_description/meshes/link_13.0.STL"/>
      </geometry>
    </visual>
    <collision>
      <origin rpy="0.0 0 0.0" xyz=" 0 0 0.01 "/>
      <geometry>
        <cylinder length="0.02" radius="0.0115"/>
      </geometry>
    </collision>
  </link>
  <joint name="ahand/thumb/dof2_joint" type="revolute">
    <parent link="ahand/thumb/dof1_link"/>
    <child link="ahand/thumb/dof2_link"/>
    <origin rpy="-1.57079632679 0 1.57079632679" xyz="0 0 0.0177"/>
    <axis xyz="0 0 1"/>
    <limit effort="100" lower="-0.188495559215" upper="1.64060949687" velocity="100"/>
    <dynamics damping="0.005" friction="0.0"/>
  </joint>
  <gazebo reference="ahand/thumb/dof2_joint">
    <provideFeedback>true</provideFeedback>
    <implicitSpringDamper>true</implicitSpringDamper>
    <!--<kp>0.0</kp>[> CFM <]-->
    <!--<kd>0.0</kd>[> ERP <]-->
    <!--<cfmDamping>true</cfmDamping>-->
    <!--<dynamics damping="5.5" friction="1"/>-->
  </gazebo>
  <gazebo reference="ahand/thumb/dof2_link">
    <mu1>0.15</mu1>
    <mu2>0.15</mu2>
    <!-- This defines the springiness of the contacts: 400000 -->
    <kp>400000</kp>
    <selfCollide>false</selfCollide>
    <material>Gazebo/Grey</material>
  </gazebo>
  <link name="ahand/thumb/dof2_link">
    <inertial>
      <origin xyz="0.00 -0.028 0.00 "/>
      <inertia ixx="1.2325e-05" ixy="0" ixz="0" iyy="3.4e-06" iyz="0" izz="1.2325e-05"/>
      <mass value="0.051"/>
    </inertial>
    <visual>
      <material name="black"/>
      <origin rpy="1.57079632679 0.0 0.0" xyz="0 0 0"/>
      <geometry>
        <mesh filename="package://allegro_hand_description/meshes/link_14.0.STL"/>
      </geometry>
    </visual>
    <collision>
      <origin rpy="1.57079632679 0 0.0" xyz=" 0 -0.027 0 "/>
      <geometry>
        <cylinder length="0.035" radius="0.0115"/>
      </geometry>
    </collision>
  </link>
  <joint name="ahand/thumb/dof3_joint" type="revolute">
    <parent link="ahand/thumb/dof2_link"/>
    <child link="ahand/thumb/dof3_link"/>
    <origin rpy="0 0 -1.57079632679" xyz="0 -0.0514 0"/>
    <axis xyz="0 0 1"/>
    <limit effort="100" lower="-0.0872664625997" upper="1.71042266695" velocity="100"/>
    <dynamics damping="0.005" friction="0.0"/>
  </joint>
  <gazebo reference="ahand/thumb/dof3_joint">
    <provideFeedback>true</provideFeedback>
    <implicitSpringDamper>true</implicitSpringDamper>
    <!--<kp>0.0</kp>[> CFM <]-->
    <!--<kd>0.0</kd>[> ERP <]-->
    <!--<cfmDamping>true</cfmDamping>-->
    <!--<dynamics damping="5.5" friction="1"/>-->
  </gazebo>
  <gazebo reference="ahand/thumb/dof3_link">
    <mu1>0.15</mu1>
    <mu2>0.15</mu2>
    <!-- This defines the springiness of the contacts: 400000 -->
    <kp>400000</kp>
    <selfCollide>false</selfCollide>
    <material>Gazebo/Grey</material>
  </gazebo>
  <link name="ahand/thumb/dof3_link">
    <inertial>
      <origin xyz="0.025 0.0 0.0 "/>
      <inertia ixx="2.82666666667e-06" ixy="0" ixz="0" iyy="7.06666666667e-06" iyz="0" izz="7.06666666667e-06"/>
      <mass value="0.0424"/>
    </inertial>
    <visual>
      <origin rpy="1.57079632679 0 1.57079632679 " xyz="-0.0 0.0 0.0"/>
      <material name="black"/>
      <geometry>
        <mesh filename="package://allegro_hand_description/meshes/link_15.0.STL"/>
      </geometry>
    </visual>
    <collision>
      <origin rpy="1.57079632679 0 1.57079632679" xyz="0.014 0 0 "/>
      <!-- 0.014 ->0.03 -->
      <geometry>
        <cylinder length="0.034" radius="0.0115"/>
      </geometry>
    </collision>
  </link>
  <joint name="ahand/thumb/dof4_joint" type="fixed">
    <parent link="ahand/thumb/dof3_link"/>
    <child link="ahand/thumb/dof4_link"/>
    <origin rpy="0 0 0" xyz="0.030 0 0"/>
  </joint>
  <link name="ahand/thumb/dof4_link">
    <inertial>
      <origin xyz="0.01 0.0 0.0 "/>
      <mass value="0.0176"/>
      <inertia ixx="6.66666666667e-09" ixy="0" ixz="0" iyy="6.66666666667e-09" iyz="0" izz="6.66666666667e-09"/>
    </inertial>
    <gazebo reference="ahand/thumb/dof3_link">
      <mu1>0.15</mu1>
      <mu2>0.15</mu2>
      <!-- This defines the springiness of the contacts: 400000 -->
      <kp>400000</kp>
      <selfCollide>true</selfCollide>
      <material>Gazebo/Grey</material>
      <material>Gazebo/White</material>
    </gazebo>
    <visual>
      <origin rpy="1.57079632679 0 1.57079632679" xyz="0.013 0 0"/>
      <material name="white">
        <color rgba=".9 .9 .9 1"/>
      </material>
      <geometry>
        <mesh filename="package://allegro_hand_description/meshes/link_15.0_tip.STL"/>
      </geometry>
    </visual>
    <collision name="ahand/thumb/dof4_link_collision">
      <origin rpy="0 0 -1.57079632679" xyz=" 0.01 0 0 "/>
      <geometry>
        <sphere radius="0.01"/>
      </geometry>
    </collision>
  </link>
</robot>

